<?xml version="1.0" encoding="utf-8"?>
<robot
  name="urdf">
  <link
    name="base_link">
    <inertial>
      <origin
        xyz="-1.1833E-17 6.993E-16 -0.18893"
        rpy="0 0 0" />
      <mass
        value="100.00" />
      <inertia
        ixx="2.1994"
        ixy="-6.9796E-16"
        ixz="-1.0409E-15"
        iyy="5.8335"
        iyz="-6.0685E-15"
        izz="7.3738" />
    </inertial>
    <visual>
      <origin
        xyz="0 0 0"
        rpy="0 0 0" />
      <geometry>
        <mesh
          filename="../meshes/base_link.STL" />
      </geometry>
      <material
        name="">
        <color
          rgba="0.92941 1 0.95686 1" />
      </material>
    </visual>
    <collision>
      <origin
        xyz="0 0 0"
        rpy="0 0 0" />
      <geometry>
        <mesh
          filename="../meshes/base_link.STL" />
      </geometry>
    </collision>
  </link>
  <link
    name="lb_Link">
    <inertial>
      <origin
        xyz="-0.167137972568874 0.000576453381228637 -0.0981771092292079"
        rpy="0 0 0" />
      <mass
        value="5" />
      <inertia
        ixx="0.0663395313797743"
        ixy="-0.0198368647273712"
        ixz="-0.052891266693704"
        iyy="0.130501097881963"
        iyz="-0.0131143090440989"
        izz="0.0965282148403548" />
    </inertial>
    <visual>
      <origin
        xyz="0 0 0"
        rpy="0 0 0" />
      <geometry>
        <mesh
          filename="../meshes/lb_Link.STL" />
      </geometry>
      <material
        name="">
        <color
          rgba="0.792156862745098 0.819607843137255 0.933333333333333 1" />
      </material>
    </visual>
    <collision>
      <origin
        xyz="0 0 0"
        rpy="0 0 0" />
      <geometry>
        <mesh
          filename="../meshes/lb_Link.STL" />
      </geometry>
  </collision>
  </link>
  <joint
    name="g_lb"
    type="revolute">
    <origin
      xyz="-0.1 0.3 -0.28"
      rpy="0 0 0" />
    <parent
      link="base_link" />
    <child
      link="lb_Link" />
    <axis
      xyz="0 1 0" />
    <limit
      lower="-0.35"
      upper="0.35"
      effort="500"
      velocity="5" />
    <dynamics
      damping="0.1"
      friction="0.1" />
    <safety_controller
      soft_upper_limit="0.4"
      soft_lower_limit="-0.4"
      k_position="10"
      k_velocity="5" />
  </joint>
  <link
    name="w_lb">
    <inertial>
      <origin
        xyz="0 -0.0348147111715202 -2.22044604925031E-16"
        rpy="0 0 0" />
      <mass
        value="3.0" />
      <inertia
        ixx="0.0028"
        ixy="0"
        ixz="0"
        iyy="0.0038"
        iyz="0"
        izz="0.0028" />
    </inertial>
    <visual>
      <origin
        xyz="0 0 0"
        rpy="0 0 0" />
      <geometry>
        <mesh
          filename="../meshes/w_lb.STL" />
      </geometry>
      <material
        name="">
        <color
          rgba="0.792156862745098 0.819607843137255 0.933333333333333 1" />
      </material>
    </visual>
    <collision>
      <origin
        xyz="0 0 0"
        rpy="0 0 0" />
      <geometry>
        <mesh
          filename="../meshes/w_lb.STL" />
      </geometry>
    </collision>
  </link>
  <joint
    name="w_lb"
    type="continuous">
    <origin
      xyz="-0.38089 0.1 -0.23963"
      rpy="0 0 0" />
    <parent
      link="lb_Link" />
    <child
      link="w_lb" />
    <axis
      xyz="0 -1 0" />
    <dynamics
      damping="0.1"
      friction="0.1" />
  </joint>
  <link
    name="lf_Link">
    <inertial>
      <origin
        xyz="0.182162464509715 0.000576453381228526 -0.0662622303788842"
        rpy="0 0 0" />
      <mass
        value="5" />
      <inertia
        ixx="0.0484781635635341"
        ixy="0.0218850219603635"
        ixz="0.0440368760588216"
        iyy="0.130501097881963"
        iyz="-0.00930226411743767"
        izz="0.114389582656595" />
    </inertial>
    <visual>
      <origin
        xyz="0 0 0"
        rpy="0 0 0" />
      <geometry>
        <mesh
          filename="../meshes/lf_Link.STL" />
      </geometry>
      <material
        name="">
        <color
          rgba="0.792156862745098 0.819607843137255 0.933333333333333 1" />
      </material>
    </visual>
    <collision>
      <origin
        xyz="0 0 0"
        rpy="0 0 0" />
      <geometry>
        <mesh
          filename="../meshes/lf_Link.STL" />
      </geometry>
    </collision>
  </link>
  <joint
    name="g_lf"
    type="revolute">
    <origin
      xyz="0.1 0.3 -0.28"
      rpy="0 0 0" />
    <parent
      link="base_link" />
    <child
      link="lf_Link" />
    <axis
      xyz="0 1 0" />
    <limit
      lower="-0.35"
      upper="0.35"
      effort="500"
      velocity="5" />
    <dynamics
      damping="0.1"
      friction="0.1" />
    <safety_controller
      soft_upper_limit="0.4"
      soft_lower_limit="-0.4"
      k_position="10"
      k_velocity="5" />
  </joint>
  <link
    name="w_lf">
    <inertial>
      <origin
        xyz="-1.1102E-16 -0.034815 -1.1102E-16"
        rpy="0 0 0" />
      <mass
        value="3" />
      <inertia
        ixx="0.0028"
        ixy="0"
        ixz="0"
        iyy="0.0038"
        iyz="0"
        izz="0.0028" />
    </inertial>
    <visual>
      <origin
        xyz="0 0 0"
        rpy="0 0 0" />
      <geometry>
        <mesh
          filename="../meshes/w_lf.STL" />
      </geometry>
      <material
        name="">
        <color
          rgba="0.79216 0.81961 0.93333 1" />
      </material>
    </visual>
    <collision>
      <origin
        xyz="0 0 0"
        rpy="0 0 0" />
      <geometry>
        <mesh
          filename="../meshes/w_lf.STL" />
      </geometry>
    </collision>
  </link>
  <joint
    name="w_lf"
    type="continuous">
    <origin
      xyz="0.41801041206503 0.100000000000001 -0.166635216581701"
      rpy="0 0 0" />
    <parent
      link="lf_Link" />
    <child
      link="w_lf" />
    <axis
      xyz="0 -1 0" />
    <dynamics
      damping="0.1"
      friction="0.1" />
  </joint>
  <link
    name="rf_Link">
    <inertial>
      <origin
        xyz="0.168550228896527 -0.00057645338122797 -0.0957322672350638"
        rpy="0 0 0" />
      <mass
        value="5" />
      <inertia
        ixx="0.0648053370600335"
        ixy="-0.0200257752517811"
        ixz="0.0524291620528891"
        iyy="0.130501097881963"
        iyz="0.0128239864894397"
        izz="0.098062409160096" />
    </inertial>
    <visual>
      <origin
        xyz="0 0 0"
        rpy="0 0 0" />
      <geometry>
        <mesh
          filename="../meshes/rf_Link.STL" />
      </geometry>
      <material
        name="">
        <color
          rgba="0.792156862745098 0.819607843137255 0.933333333333333 1" />
      </material>
    </visual>
    <collision>
      <origin
        xyz="0 0 0"
        rpy="0 0 0" />
      <geometry>
        <mesh
          filename="../meshes/rf_Link.STL" />
      </geometry>
    </collision>
  </link>
  <joint
    name="g_rf"
    type="revolute">
    <origin
      xyz="0.1 -0.3 -0.28"
      rpy="0 0 0" />
    <parent
      link="base_link" />
    <child
      link="rf_Link" />
    <axis
      xyz="0 -1 0" />
    <limit
      lower="-0.35"
      upper="0.35"
      effort="500"
      velocity="5" />
    <dynamics
      damping="0.1"
      friction="0.1" />
    <safety_controller
      soft_upper_limit="0.4"
      soft_lower_limit="-0.4"
      k_position="10"
      k_velocity="5" />
  </joint>
  <link
    name="w_rf">
    <inertial>
      <origin
        xyz="5.5511E-17 0.034815 3.3307E-16"
        rpy="0 0 0" />
      <mass
        value="3" />
      <inertia
        ixx="0.0028"
        ixy="0"
        ixz="0"
        iyy="0.0038"
        iyz="0"
        izz="0.0028" />
    </inertial>
    <visual>
      <origin
        xyz="0 0 0"
        rpy="0 0 0" />
      <geometry>
        <mesh
          filename="../meshes/w_rf.STL" />
      </geometry>
      <material
        name="">
        <color
          rgba="0.79216 0.81961 0.93333 1" />
      </material>
    </visual>
    <collision>
      <origin
        xyz="0 0 0"
        rpy="0 0 0" />
      <geometry>
        <mesh
          filename="../meshes/w_rf.STL" />
      </geometry>
    </collision>
  </link>
  <joint
    name="w_rf"
    type="continuous">
    <origin
      xyz="0.38434 -0.1 -0.23406"
      rpy="0 0 0" />
    <parent
      link="rf_Link" />
    <child
      link="w_rf" />
    <axis
      xyz="0 1 0" />
    <dynamics
      damping="0.1"
      friction="0.1" />
  </joint>
  <link
    name="rb_Link">
    <inertial>
      <origin
        xyz="-0.168550228896527 -0.00057645338122797 -0.0957322672350638"
        rpy="0 0 0" />
      <mass
        value="5" />
      <inertia
        ixx="0.0648053370600335"
        ixy="-0.0200257752517811"
        ixz="0.0524291620528891"
        iyy="0.130501097881963"
        iyz="0.0128239864894397"
        izz="0.098062409160096" />
    </inertial>
    <visual>
      <origin
        xyz="0 0 0"
        rpy="0 0 0" />
      <geometry>
        <mesh
          filename="../meshes/rb_Link.STL" />
      </geometry>
      <material
        name="">
        <color
          rgba="1 1 1 1" />
      </material>
    </visual>
    <collision>
      <origin
        xyz="0 0 0"
        rpy="0 0 0" />
      <geometry>
        <mesh
          filename="../meshes/rb_Link.STL" />
      </geometry>
    </collision>
  </link>
  <joint
    name="g_rb"
    type="revolute">
    <origin
      xyz="-0.1 -0.3 -0.28"
      rpy="0 0 0" />
    <parent
      link="base_link" />
    <child
      link="rb_Link" />
    <axis
      xyz="0 -1 0" />
    <limit
      lower="-0.35"
      upper="0.35"
      effort="500"
      velocity="5" />
    <dynamics
      damping="0.1"
      friction="0.1" />
    <safety_controller
      soft_upper_limit="0.4"
      soft_lower_limit="-0.4"
      k_position="10"
      k_velocity="5" />
  </joint>
  <link
    name="w_rb">
    <inertial>
      <origin
        xyz="0 0.0348147111715202 1.66533453693773E-16"
        rpy="0 0 0" />
      <mass
        value="3" />
      <inertia
        ixx="0.0028"
        ixy="0"
        ixz="0"
        iyy="0.0038"
        iyz="0"
        izz="0.0028" />
    </inertial>
    <visual>
      <origin
        xyz="0 0 0"
        rpy="0 0 0" />
      <geometry>
        <mesh
          filename="../meshes/w_rb.STL" />
      </geometry>
      <material
        name="">
        <color
          rgba="0.792156862745098 0.819607843137255 0.933333333333333 1" />
      </material>
    </visual>
    <collision>
      <origin
        xyz="0 0 0"
        rpy="0 0 0" />
      <geometry>
        <mesh
          filename="../meshes/w_rb.STL" />
      </geometry>
    </collision>
  </link>
  <joint
    name="w_rb"
    type="continuous">
    <origin
      xyz="-0.39963 -0.1 -0.20687"
      rpy="0 0 0" />
    <parent
      link="rb_Link" />
    <child
      link="w_rb" />
    <axis
      xyz="0 1 0" />
    <dynamics
      damping="0.1"
      friction="0.1" />
  </joint>
    <mujoco>
        <compiler balanceinertia="true" discardvisual="false" meshdir="../meshes"/>
    </mujoco>
</robot>
</robot>
